Workbook

Sheet Start Here
A1: replay test
A3: THE SLATE
A4: Game | B4: Kickoff | C4: Favorite | D4: Total | E4: Legs priced
A5: PIT @ CLE | B5: Thu 08:15 PM ET | C5: PIT -2.5 | D5: 39 | E5: 67
A7: INJURIES AT A GLANCE (details on Injuries & Notes)
A8: Removed from the model: Rico Dowdle
A9: KC Concepcion (CLE) - Not out
A10: Tylan Wallace (CLE) - Not official
A11: Joey Porter Jr. (PIT) - Out (traded to DAL)
A12: Jalen Ramsey / Brandin Echols (PIT) - Questionable
A13: Elgton Jenkins (CLE) - Out
A15: HOW TO USE (4 steps)
A16: 1. Scan Best Legs or Top Entries for ideas.
A17: 2. Shortcut: Payout Finder lists the best entries per size and the multiplier each needs to be a PLAY.
A18: Or build any entry in the Entry Builder: pick each leg from the dropdowns, using the PrizePicks line.
A19: 3. Type the app's multiplier (and bankroll if you want a stake). Read the verdict: PLAY or SKIP.
... A22: TABS (click to jump)
A23: Entry Builder | B23: Build and check any entry: verdict, EV, stake, the math
A24: Payout Finder | B24: Top entries by size with EV at every multiplier - find PLAY fast
A25: Top Entries | B25: Best combinations at standard payouts
A26: Best Legs | B26: Strongest single picks near the book line
A27: Player Lines | B27: Every player's full ladder of lines
A28: Injuries & Notes | B28: Who is out and what the model assumes
A29: Learn the Math | B29: Formulas and an EV cheat sheet
A30: Settings | B30: Cushion, safety cut, stake size, standard payouts
A32: COLORS
A33: Yellow = you fill in
A34: Green = good / clears the bar
A35: Red = bad / below the bar

Sheet Entry Builder
A1: Entry Builder
A2: Pick each leg from the dropdowns (Player, then Stat, then More/Less, then Line). Type the app's multiplier. The verdict updates instantly.
A3: Yellow = you fill in. Lines: pick from the list or type the PrizePicks line if it differs. Free space = a promo leg (counted as 99%).
A5: YOUR LEGS
A6: Leg | B6: Player | C6: Stat | D6: More / Less | E6: Line | F6: Free space? | G6: Book line | H6: Chance it hits | K6: key | L6: sim col | M6: used | N6: live | O6: team | P6: type | Q6: stack x | R6: after cut | S6: cut ratio
A7: 1 | B7: Denzel Boston | C7: Receptions | D7: More | E7: 2.5 | G7: =IF(K7="","",IFERROR(INDEX(Lists!$K$2:$K$68,MATCH(K7,Lists!$I$2:$I$68,0)),"")) | H7: =IF(M7=0,"",IF(F7="Yes",0.99,IF(D7="Less",COUNTIF(INDEX(Sims!$A$2:$BO$2001,0,L7),"<"&E7),COUNTIF(INDEX(Sims!$A$2:$BO$2001,0,L7),">"&E7))/2000)) | K7: =IF(OR(B7="",C7=""),"",B7&" | "&C7) | L7: =IF(K7="",0,IFERROR(MATCH(K7,Sims!$1:$1,0),0)) | M7: =IF(AND(L7>0,D7<>"",E7<>""),1,0) | N7: =IF(AND(M7=1,F7<>"Yes"),1,0) | O7: =IF(K7="","",IFERROR(INDEX(Lists!$J$2:$J$68,MATCH(K7,Lists!$I$2:$I$68,0)),"")) | P7: =IF(C7="Pass Yds","QBY",IF(C7="Pass TDs","QBTD",IF(OR(C7="Rec Yds",C7="Receptions",C7="Rush+Rec Yds"),"REC",IF(C7="Anytime TDs","TD","OTHER")))) | Q7: =IF(N7=0,1,IF(P7="QBY",CHOOSE(MIN(COUNTIFS($O$7:$O$12,O7,$P$7:$P$12,"REC",$D$7:$D$12,D7,$N$7:$N$12,1),3)+1,1,1,0.95,0.9),IF(AND(P7="QBTD",D7="More",COUNTIFS($O$7:$O$12,O7,$P$7:$P$12,"TD",$D$7:$D$12,"More",$N$7:$N$12,1)>=1),0.9,1))) | R7: =IF(N7=1,MAX(H7-Settings!$B$5,0.01),"") | S7: =IF(N7=1,R7/H7,1)
A8: 2 | B8: Raheim Sanders | C8: Receptions | D8: More | E8: 1.5 | G8: =IF(K8="","",IFERROR(INDEX(Lists!$K$2:$K$68,MATCH(K8,Lists!$I$2:$I$68,0)),"")) | H8: =IF(M8=0,"",IF(F8="Yes",0.99,IF(D8="Less",COUNTIF(INDEX(Sims!$A$2:$BO$2001,0,L8),"<"&E8),COUNTIF(INDEX(Sims!$A$2:$BO$2001,0,L8),">"&E8))/2000)) | K8: =IF(OR(B8="",C8=""),"",B8&" | "&C8) | L8: =IF(K8="",0,IFERROR(MATCH(K8,Sims!$1:$1,0),0)) | M8: =IF(AND(L8>0,D8<>"",E8<>""),1,0) | N8: =IF(AND(M8=1,F8<>"Yes"),1,0) | O8: =IF(K8="","",IFERROR(INDEX(Lists!$J$2:$J$68,MATCH(K8,Lists!$I$2:$I$68,0)),"")) | P8: =IF(C8="Pass Yds","QBY",IF(C8="Pass TDs","QBTD",IF(OR(C8="Rec Yds",C8="Receptions",C8="Rush+Rec Yds"),"REC",IF(C8="Anytime TDs","TD","OTHER")))) | Q8: =IF(N8=0,1,IF(P8="QBY",CHOOSE(MIN(COUNTIFS($O$7:$O$12,O8,$P$7:$P$12,"REC",$D$7:$D$12,D8,$N$7:$N$12,1),3)+1,1,1,0.95,0.9),IF(AND(P8="QBTD",D8="More",COUNTIFS($O$7:$O$12,O8,$P$7:$P$12,"TD",$D$7:$D$12,"More",$N$7:$N$12,1)>=1),0.9,1))) | R8: =IF(N8=1,MAX(H8-Settings!$B$5,0.01),"") | S8: =IF(N8=1,R8/H8,1)
A9: 3 | B9: Aaron Rodgers | C9: Pass Yds | D9: Less | E9: 212.5 | G9: =IF(K9="","",IFERROR(INDEX(Lists!$K$2:$K$68,MATCH(K9,Lists!$I$2:$I$68,0)),"")) | H9: =IF(M9=0,"",IF(F9="Yes",0.99,IF(D9="Less",COUNTIF(INDEX(Sims!$A$2:$BO$2001,0,L9),"<"&E9),COUNTIF(INDEX(Sims!$A$2:$BO$2001,0,L9),">"&E9))/2000)) | K9: =IF(OR(B9="",C9=""),"",B9&" | "&C9) | L9: =IF(K9="",0,IFERROR(MATCH(K9,Sims!$1:$1,0),0)) | M9: =IF(AND(L9>0,D9<>"",E9<>""),1,0) | N9: =IF(AND(M9=1,F9<>"Yes"),1,0) | O9: =IF(K9="","",IFERROR(INDEX(Lists!$J$2:$J$68,MATCH(K9,Lists!$I$2:$I$68,0)),"")) | P9: =IF(C9="Pass Yds","QBY",IF(C9="Pass TDs","QBTD",IF(OR(C9="Rec Yds",C9="Receptions",C9="Rush+Rec Yds"),"REC",IF(C9="Anytime TDs","TD","OTHER")))) | Q9: =IF(N9=0,1,IF(P9="QBY",CHOOSE(MIN(COUNTIFS($O$7:$O$12,O9,$P$7:$P$12,"REC",$D$7:$D$12,D9,$N$7:$N$12,1),3)+1,1,1,0.95,0.9),IF(AND(P9="QBTD",D9="More",COUNTIFS($O$7:$O$12,O9,$P$7:$P$12,"TD",$D$7:$D$12,"More",$N$7:$N$12,1)>=1),0.9,1))) | R9: =IF(N9=1,MAX(H9-Settings!$B$5,0.01),"") | S9: =IF(N9=1,R9/H9,1)
A10: 4 | B10: DK Metcalf | C10: Rush+Rec Yds | D10: Less | E10: 42.5 | G10: =IF(K10="","",IFERROR(INDEX(Lists!$K$2:$K$68,MATCH(K10,Lists!$I$2:$I$68,0)),"")) | H10: =IF(M10=0,"",IF(F10="Yes",0.99,IF(D10="Less",COUNTIF(INDEX(Sims!$A$2:$BO$2001,0,L10),"<"&E10),COUNTIF(INDEX(Sims!$A$2:$BO$2001,0,L10),">"&E10))/2000)) | K10: =IF(OR(B10="",C10=""),"",B10&" | "&C10) | L10: =IF(K10="",0,IFERROR(MATCH(K10,Sims!$1:$1,0),0)) | M10: =IF(AND(L10>0,D10<>"",E10<>""),1,0) | N10: =IF(AND(M10=1,F10<>"Yes"),1,0) | O10: =IF(K10="","",IFERROR(INDEX(Lists!$J$2:$J$68,MATCH(K10,Lists!$I$2:$I$68,0)),"")) | P10: =IF(C10="Pass Yds","QBY",IF(C10="Pass TDs","QBTD",IF(OR(C10="Rec Yds",C10="Receptions",C10="Rush+Rec Yds"),"REC",IF(C10="Anytime TDs","TD","OTHER")))) | Q10: =IF(N10=0,1,IF(P10="QBY",CHOOSE(MIN(COUNTIFS($O$7:$O$12,O10,$P$7:$P$12,"REC",$D$7:$D$12,D10,$N$7:$N$12,1),3)+1,1,1,0.95,0.9),IF(AND(P10="QBTD",D10="More",COUNTIFS($O$7:$O$12,O10,$P$7:$P$12,"TD",$D$7:$D$12,"More",$N$7:$N$12,1)>=1),0.9,1))) | R10: =IF(N10=1,MAX(H10-Settings!$B$5,0.01),"") | S10: =IF(N10=1,R10/H10,1)
A11: 5 | G11: =IF(K11="","",IFERROR(INDEX(Lists!$K$2:$K$68,MATCH(K11,Lists!$I$2:$I$68,0)),"")) | H11: =IF(M11=0,"",IF(F11="Yes",0.99,IF(D11="Less",COUNTIF(INDEX(Sims!$A$2:$BO$2001,0,L11),"<"&E11),COUNTIF(INDEX(Sims!$A$2:$BO$2001,0,L11),">"&E11))/2000)) | K11: =IF(OR(B11="",C11=""),"",B11&" | "&C11) | L11: =IF(K11="",0,IFERROR(MATCH(K11,Sims!$1:$1,0),0)) | M11: =IF(AND(L11>0,D11<>"",E11<>""),1,0) | N11: =IF(AND(M11=1,F11<>"Yes"),1,0) | O11: =IF(K11="","",IFERROR(INDEX(Lists!$J$2:$J$68,MATCH(K11,Lists!$I$2:$I$68,0)),"")) | P11: =IF(C11="Pass Yds","QBY",IF(C11="Pass TDs","QBTD",IF(OR(C11="Rec Yds",C11="Receptions",C11="Rush+Rec Yds"),"REC",IF(C11="Anytime TDs","TD","OTHER")))) | Q11: =IF(N11=0,1,IF(P11="QBY",CHOOSE(MIN(COUNTIFS($O$7:$O$12,O11,$P$7:$P$12,"REC",$D$7:$D$12,D11,$N$7:$N$12,1),3)+1,1,1,0.95,0.9),IF(AND(P11="QBTD",D11="More",COUNTIFS($O$7:$O$12,O11,$P$7:$P$12,"TD",$D$7:$D$12,"More",$N$7:$N$12,1)>=1),0.9,1))) | R11: =IF(N11=1,MAX(H11-Settings!$B$5,0.01),"") | S11: =IF(N11=1,R11/H11,1)
A12: 6 | G12: =IF(K12="","",IFERROR(INDEX(Lists!$K$2:$K$68,MATCH(K12,Lists!$I$2:$I$68,0)),"")) | H12: =IF(M12=0,"",IF(F12="Yes",0.99,IF(D12="Less",COUNTIF(INDEX(Sims!$A$2:$BO$2001,0,L12),"<"&E12),COUNTIF(INDEX(Sims!$A$2:$BO$2001,0,L12),">"&E12))/2000)) | K12: =IF(OR(B12="",C12=""),"",B12&" | "&C12) | L12: =IF(K12="",0,IFERROR(MATCH(K12,Sims!$1:$1,0),0)) | M12: =IF(AND(L12>0,D12<>"",E12<>""),1,0) | N12: =IF(AND(M12=1,F12<>"Yes"),1,0) | O12: =IF(K12="","",IFERROR(INDEX(Lists!$J$2:$J$68,MATCH(K12,Lists!$I$2:$I$68,0)),"")) | P12: =IF(C12="Pass Yds","QBY",IF(C12="Pass TDs","QBTD",IF(OR(C12="Rec Yds",C12="Receptions",C12="Rush+Rec Yds"),"REC",IF(C12="Anytime TDs","TD","OTHER")))) | Q12: =IF(N12=0,1,IF(P12="QBY",CHOOSE(MIN(COUNTIFS($O$7:$O$12,O12,$P$7:$P$12,"REC",$D$7:$D$12,D12,$N$7:$N$12,1),3)+1,1,1,0.95,0.9),IF(AND(P12="QBTD",D12="More",COUNTIFS($O$7:$O$12,O12,$P$7:$P$12,"TD",$D$7:$D$12,"More",$N$7:$N$12,1)>=1),0.9,1))) | R12: =IF(N12=1,MAX(H12-Settings!$B$5,0.01),"") | S12: =IF(N12=1,R12/H12,1)
A14: YOUR PAYOUT
A15: Play type | D15: Power | E15: Power = every leg must hit. Flex = partial payouts (3+ legs).
A16: App multiplier if ALL legs hit ('To Win') | E16: From the app, e.g. 5.25. Blank = standard payout (less accurate).
A17: Flex only: multiplier with 1 miss | E17: From the app when Flex is selected.
A18: Flex only: multiplier with 2 misses | E18: 5-6 leg Flex only.
A19: Your bankroll ($) - optional | E19: Money set aside for betting. Used only for the suggested stake.
A21: THE DECISION | J21: legs used | K21: =SUM($M$7:$M$12)
A22: Verdict | C22: =IF(K21<2,"Add at least 2 legs",IF(K40>0,"FIX LEGS",IF(AND(D15="Flex",K21<3),"Flex needs 3+ legs",IF(K35="","Enter the multiplier",IF(K35<=0,"SKIP",IF(K35<K36,"SKIP","PLAY")))))) | J22: live legs | K22: =SUM($N$7:$N$12)
A23: =IF(K21<2,"",IF(K40>0,"This entry breaks a PrizePicks rule - see CHECKS below.",IF(K35="","",IF(K35<=0,"Loses money on average ("&TEXT(K35,"+0%;-0%")&" per $1).",IF(K35<K36,"Positive ("&TEXT(K35,"+0%")&") but below the "&TEXT(K36,"+0%")&" cushion for "&K22&" live legs. Too thin to trust.","Clears the "&TEXT(K36,"+0%")&" cushion with "&TEXT(K35,"+0%")&" expected profit per $1.")))))&IF(D16="",IF(K21>=2," Using the STANDARD payout - type the app multiplier.",""),"") | J23: free legs | K23: =K21-K22
J24: all hit raw | K24: =IF(K21<1,"",COUNTIF(Calc!$G$2:$G$2001,0)/2000)
A25: Chance ALL legs hit | D25: =K30 | E25: Includes how the legs move together, stack corrections, and the safety cut. | J25: one miss raw | K25: =IF(K21<1,"",COUNTIF(Calc!$G$2:$G$2001,1)/2000)
A26: Break-even (chance needed) | D26: =IF(K32="","",IF(D15="Flex","see EV (Flex pays partial wins)",1/K32)) | E26: 1 / payout. The entry must hit at least this often. | J26: two miss raw | K26: =IF(K21<1,"",COUNTIF(Calc!$G$2:$G$2001,2)/2000)
A27: Expected profit per $1 (EV) | D27: =K35 | E27: Average over many entries like this - not tonight. | J27: stack factor | K27: =PRODUCT($Q$7:$Q$12)
A28: Cushion needed | D28: =IF(K21<2,"",K36) | E28: 5% per live leg (Settings). Free spaces do not count. | J28: cut factor | K28: =PRODUCT($S$7:$S$12)
A29: Suggested stake | D29: =IF(D19="","add bankroll",K37) | E29: Quarter-Kelly. $0 unless the verdict is PLAY. | J29: independent | K29: =IF(K21<1,"",PRODUCT($H$7:$H$12))
A30: Chance this entry loses | D30: =IF(K30="","",IF(D15="Flex",1-K30-K25*(K38>0)-K26*(K39>0),1-K30)) | E30: Losing streaks are normal even when EV is positive. | J30: all hit | K30: =IF(K21<1,"",K24*K27*K28*0.99^K23)
J31: default payout | K31: =IFERROR(IF(D15="Flex",INDEX(Settings!$C$11:$C$15,MATCH(K21,Settings!$A$11:$A$15,0)),INDEX(Settings!$B$11:$B$15,MATCH(K21,Settings!$A$11:$A$15,0))),"")
A32: CHECKS | J32: payout | K32: =IF(D16<>"",D16,K31)
A33: =IF(SUMPRODUCT(($B$7:$B$12<>"")*(COUNTIF($B$7:$B$12,$B$7:$B$12)>1))>0,"Same player picked twice - PrizePicks does not allow that.","") | J33: power EV | K33: =IF(OR(K21<2,K32=""),"",K30*K32-1)
A34: =IF(AND(K21>=2,SUMPRODUCT(($O$7:$O$12<>"")/COUNTIF($O$7:$O$12,$O$7:$O$12&""))=1),"All legs are from one team - PrizePicks needs at least 2 teams.","") | J34: flex EV | K34: =IF(OR(K21<3,K32=""),"",K30*K32+K25*K38+K26*K39-1)
A35: =IF(COUNTIFS($C$7:$C$12,"Anytime TDs",$D$7:$D$12,"Less")>0,"Anytime TD Less is not offered on PrizePicks (More only).","") | J35: EV | K35: =IF(D15="Flex",K34,K33)
A36: =IF(SUMPRODUCT(($B$7:$B$12<>"")*(1-$M$7:$M$12))>0,"A leg is missing its stat, side or line - it is being ignored.","") | J36: cushion | K36: =K22*Settings!$B$6
A37: =IF(K27<1,"Stack correction applied: x"&TEXT(K27,"0.00")&" (the model slightly overrates QB + his receivers going the same way).","") | J37: stake | K37: =IF(OR(D19="",K35="",K32=""),"",IF(OR(K35<K36,K35<=0,K40>0),0,FLOOR(D19*Settings!$B$7*K35/(K32-1),0.25)))
A38: =IF(AND(K21>=2,K40=0),"No PrizePicks rule problems found.","") | J38: flex 1-miss pay | K38: =IF(D17<>"",D17,IFERROR(INDEX(Settings!$D$11:$D$15,MATCH(K21,Settings!$A$11:$A$15,0)),0))
A39: SHOW THE MATH | J39: flex 2-miss pay | K39: =IF(D18<>"",D18,IFERROR(INDEX(Settings!$E$11:$E$15,MATCH(K21,Settings!$A$11:$A$15,0)),0))
A40: 1. If the legs were unrelated, multiply them | D40: =IF(K21<2,"",IF(H7="","",TEXT(H7,"0.0%"))&IF(H8="",""," x "&TEXT(H8,"0.0%"))&IF(H9="",""," x "&TEXT(H9,"0.0%"))&IF(H10="",""," x "&TEXT(H10,"0.0%"))&IF(H11="",""," x "&TEXT(H11,"0.0%"))&IF(H12="",""," x "&TEXT(H12,"0.0%"))&" = "&TEXT(K29,"0.0%")) | J40: rule breaks | K40: =(SUMPRODUCT(($B$7:$B$12<>"")*(COUNTIF($B$7:$B$12,$B$7:$B$12)>1))>0)+AND(K21>=2,SUMPRODUCT(($O$7:$O$12<>"")/COUNTIF($O$7:$O$12,$O$7:$O$12&""))=1)+(COUNTIFS($C$7:$C$12,"Anytime TDs",$D$7:$D$12,"Less")>0)
A41: 2. Simulated together (they move as a group) | D41: =IF(K21<2,"",TEXT(K24,"0.0%")&IF(K23>0," (free space counted as a sure hit)","")&" = x"&TEXT(K24/K29,"0.00")&" vs unrelated")
A42: 3. Stack correction and safety cut | D42: =IF(K21<2,"",TEXT(K24,"0.0%")&" x "&TEXT(K27,"0.00")&" x "&TEXT(K28,"0.000")&IF(K23>0," x 0.99","")&" = "&TEXT(K30,"0.0%"))
A43: 4. Break-even | D43: =IF(K32="","","1 / "&TEXT(K32,"0.00")&"x = "&TEXT(1/K32,"0.0%"))
...

Sheet Payout Finder
A1: Payout Finder
A2: Build an entry from this list in the app, read its multiplier, find that column: GREEN = PLAY, AMBER = positive but below the cushion, RED = loses.
A3: Shortcut: 'PLAY at' is the lowest multiplier where that entry clears the cushion. Lines are book lines - if PrizePicks shows a different line, check it in the Entry Builder.
A5: 2 LEGS | B5: Cushion | C5: =2*Settings!$B$6 | D5: 2-leg entries | multipliers 2.00x to 4.00x, every 0.25x
A6: # | B6: PLAY at | C6: All hit | D6: Entry (book lines) | E6: 2 | F6: 2.25 | G6: 2.5 | H6: 2.75 | I6: 3 | J6: 3.25 | K6: 3.5 | L6: 3.75 | M6: 4
A7: 1 | B7: =(1+$C$5)/C7 | C7: =0.32740*(MAX(0.5980-Settings!$B$5,0.01)/0.5980)*(MAX(0.5490-Settings!$B$5,0.01)/0.5490) | D7: Raheim Sanders (CLE) Receptions More 1.5 [60%] Pat Freiermuth (PIT) Receptions Less 3.5 [55%] | E7: =$C7*E$6-1 | F7: =$C7*F$6-1 | G7: =$C7*G$6-1 | H7: =$C7*H$6-1 | I7: =$C7*I$6-1 | J7: =$C7*J$6-1 | K7: =$C7*K$6-1 | L7: =$C7*L$6-1 | M7: =$C7*M$6-1
A8: 2 | B8: =(1+$C$5)/C8 | C8: =0.32540*(MAX(0.5980-Settings!$B$5,0.01)/0.5980)*(MAX(0.5460-Settings!$B$5,0.01)/0.5460) | D8: Raheim Sanders (CLE) Receptions More 1.5 [60%] Jaylen Warren (PIT) Receptions Less 3.5 [55%] | E8: =$C8*E$6-1 | F8: =$C8*F$6-1 | G8: =$C8*G$6-1 | H8: =$C8*H$6-1 | I8: =$C8*I$6-1 | J8: =$C8*J$6-1 | K8: =$C8*K$6-1 | L8: =$C8*L$6-1 | M8: =$C8*M$6-1
A9: 3 | B9: =(1+$C$5)/C9 | C9: =0.32440*(MAX(0.5290-Settings!$B$5,0.01)/0.5290)*(MAX(0.5980-Settings!$B$5,0.01)/0.5980) | D9: DK Metcalf (PIT) Receptions More 3.5 [53%] Raheim Sanders (CLE) Receptions More 1.5 [60%] | E9: =$C9*E$6-1 | F9: =$C9*F$6-1 | G9: =$C9*G$6-1 | H9: =$C9*H$6-1 | I9: =$C9*I$6-1 | J9: =$C9*J$6-1 | K9: =$C9*K$6-1 | L9: =$C9*L$6-1 | M9: =$C9*M$6-1
A10: 4 | B10: =(1+$C$5)/C10 | C10: =0.31760*(MAX(0.5490-Settings!$B$5,0.01)/0.5490)*(MAX(0.5660-Settings!$B$5,0.01)/0.5660) | D10: Pat Freiermuth (PIT) Receptions Less 3.5 [55%] Jerry Jeudy (CLE) Receptions Less 1.5 [57%] | E10: =$C10*E$6-1 | F10: =$C10*F$6-1 | G10: =$C10*G$6-1 | H10: =$C10*H$6-1 | I10: =$C10*I$6-1 | J10: =$C10*J$6-1 | K10: =$C10*K$6-1 | L10: =$C10*L$6-1 | M10: =$C10*M$6-1
A11: 5 | B11: =(1+$C$5)/C11 | C11: =0.31520*(MAX(0.5700-Settings!$B$5,0.01)/0.5700)*(MAX(0.5460-Settings!$B$5,0.01)/0.5460) | D11: Denzel Boston (CLE) Receptions More 2.5 [57%] Jaylen Warren (PIT) Receptions Less 3.5 [55%] | E11: =$C11*E$6-1 | F11: =$C11*F$6-1 | G11: =$C11*G$6-1 | H11: =$C11*H$6-1 | I11: =$C11*I$6-1 | J11: =$C11*J$6-1 | K11: =$C11*K$6-1 | L11: =$C11*L$6-1 | M11: =$C11*M$6-1
A12: 6 | B12: =(1+$C$5)/C12 | C12: =0.31260*(MAX(0.5980-Settings!$B$5,0.01)/0.5980)*(MAX(0.5360-Settings!$B$5,0.01)/0.5360) | D12: Raheim Sanders (CLE) Receptions More 1.5 [60%] Michael Pittman Jr. (PIT) Receptions Less 3.5 [54%] | E12: =$C12*E$6-1 | F12: =$C12*F$6-1 | G12: =$C12*G$6-1 | H12: =$C12*H$6-1 | I12: =$C12*I$6-1 | J12: =$C12*J$6-1 | K12: =$C12*K$6-1 | L12: =$C12*L$6-1 | M12: =$C12*M$6-1
A13: 7 | B13: =(1+$C$5)/C13 | C13: =0.31260*(MAX(0.5160-Settings!$B$5,0.01)/0.5160)*(MAX(0.5980-Settings!$B$5,0.01)/0.5980) | D13: Darnell Washington (PIT) Rec Yds More 16.5 [52%] Raheim Sanders (CLE) Receptions More 1.5 [60%] | E13: =$C13*E$6-1 | F13: =$C13*F$6-1 | G13: =$C13*G$6-1 | H13: =$C13*H$6-1 | I13: =$C13*I$6-1 | J13: =$C13*J$6-1 | K13: =$C13*K$6-1 | L13: =$C13*L$6-1 | M13: =$C13*M$6-1
A14: 8 | B14: =(1+$C$5)/C14 | C14: =0.31200*(MAX(0.5220-Settings!$B$5,0.01)/0.5220)*(MAX(0.5980-Settings!$B$5,0.01)/0.5980) | D14: Jaylen Warren (PIT) Rec Yds More 22.5 [52%] Raheim Sanders (CLE) Receptions More 1.5 [60%] | E14: =$C14*E$6-1 | F14: =$C14*F$6-1 | G14: =$C14*G$6-1 | H14: =$C14*H$6-1 | I14: =$C14*I$6-1 | J14: =$C14*J$6-1 | K14: =$C14*K$6-1 | L14: =$C14*L$6-1 | M14: =$C14*M$6-1
A15: 9 | B15: =(1+$C$5)/C15 | C15: =0.31080*(MAX(0.5980-Settings!$B$5,0.01)/0.5980)*(MAX(0.5230-Settings!$B$5,0.01)/0.5230) | D15: Raheim Sanders (CLE) Receptions More 1.5 [60%] Aaron Rodgers (PIT) Rush Yds Less 1.5 [52%] | E15: =$C15*E$6-1 | F15: =$C15*F$6-1 | G15: =$C15*G$6-1 | H15: =$C15*H$6-1 | I15: =$C15*I$6-1 | J15: =$C15*J$6-1 | K15: =$C15*K$6-1 | L15: =$C15*L$6-1 | M15: =$C15*M$6-1
A16: 10 | B16: =(1+$C$5)/C16 | C16: =0.31040*(MAX(0.5360-Settings!$B$5,0.01)/0.5360)*(MAX(0.5660-Settings!$B$5,0.01)/0.5660) | D16: Michael Pittman Jr. (PIT) Receptions Less 3.5 [54%] Jerry Jeudy (CLE) Receptions Less 1.5 [57%] | E16: =$C16*E$6-1 | F16: =$C16*F$6-1 | G16: =$C16*G$6-1 | H16: =$C16*H$6-1 | I16: =$C16*I$6-1 | J16: =$C16*J$6-1 | K16: =$C16*K$6-1 | L16: =$C16*L$6-1 | M16: =$C16*M$6-1
A18: 3 LEGS | B18: Cushion | C18: =3*Settings!$B$6 | D18: 3-leg entries | multipliers 3.50x to 7.00x, every 0.25x
A19: # | B19: PLAY at | C19: All hit | D19: Entry (book lines) | E19: 3.5 | F19: 3.75 | G19: 4 | H19: 4.25 | I19: 4.5 | J19: 4.75 | K19: 5 | L19: 5.25 | M19: 5.5 | N19: 5.75 | O19: 6 | P19: 6.25 | Q19: 6.5 | R19: 6.75 | S19: 7
A20: 1 | B20: =(1+$C$18)/C20 | C20: =0.19680*(MAX(0.5700-Settings!$B$5,0.01)/0.5700)*(MAX(0.5980-Settings!$B$5,0.01)/0.5980)*(MAX(0.5460-Settings!$B$5,0.01)/0.5460) | D20: Denzel Boston (CLE) Receptions More 2.5 [57%] Raheim Sanders (CLE) Receptions More 1.5 [60%] Jaylen Warren (PIT) Receptions Less 3.5 [55%] | E20: =$C20*E$19-1 | F20: =$C20*F$19-1 | G20: =$C20*G$19-1 | H20: =$C20*H$19-1 | I20: =$C20*I$19-1 | J20: =$C20*J$19-1 | K20: =$C20*K$19-1 | L20: =$C20*L$19-1 | ... S20: =$C20*S$19-1
A21: 2 | B21: =(1+$C$18)/C21 | C21: =0.19540*(MAX(0.4960-Settings!$B$5,0.01)/0.4960)*(MAX(0.5110-Settings!$B$5,0.01)/0.5110)*(MAX(0.5980-Settings!$B$5,0.01)/0.5980) | D21: Aaron Rodgers (PIT) Pass Yds More 212.5 [50%] DK Metcalf (PIT) Rec Yds More 41.5 [51%] Raheim Sanders (CLE) Receptions More 1.5 [60%] | E21: =$C21*E$19-1 | F21: =$C21*F$19-1 | G21: =$C21*G$19-1 | H21: =$C21*H$19-1 | I21: =$C21*I$19-1 | J21: =$C21*J$19-1 | K21: =$C21*K$19-1 | L21: =$C21*L$19-1 | ... S21: =$C21*S$19-1
A22: 3 | B22: =(1+$C$18)/C22 | C22: =0.19260*(MAX(0.5980-Settings!$B$5,0.01)/0.5980)*(MAX(0.5040-Settings!$B$5,0.01)/0.5040)*(MAX(0.5000-Settings!$B$5,0.01)/0.5000) | D22: Raheim Sanders (CLE) Receptions More 1.5 [60%] Aaron Rodgers (PIT) Pass Yds Less 212.5 [50%] DK Metcalf (PIT) Rush+Rec Yds Less 42.5 [50%] | E22: =$C22*E$19-1 | F22: =$C22*F$19-1 | G22: =$C22*G$19-1 | H22: =$C22*H$19-1 | I22: =$C22*I$19-1 | J22: =$C22*J$19-1 | K22: =$C22*K$19-1 | L22: =$C22*L$19-1 | ... S22: =$C22*S$19-1
A23: 4 | B23: =(1+$C$18)/C23 | C23: =0.18440*(MAX(0.5700-Settings!$B$5,0.01)/0.5700)*(MAX(0.5040-Settings!$B$5,0.01)/0.5040)*(MAX(0.4890-Settings!$B$5,0.01)/0.4890) | D23: Denzel Boston (CLE) Receptions More 2.5 [57%] Aaron Rodgers (PIT) Pass Yds Less 212.5 [50%] DK Metcalf (PIT) Rec Yds Less 41.5 [49%] | E23: =$C23*E$19-1 | F23: =$C23*F$19-1 | G23: =$C23*G$19-1 | H23: =$C23*H$19-1 | I23: =$C23*I$19-1 | J23: =$C23*J$19-1 | K23: =$C23*K$19-1 | L23: =$C23*L$19-1 | ... S23: =$C23*S$19-1
A24: 5 | B24: =(1+$C$18)/C24 | C24: =0.18420*(MAX(0.4960-Settings!$B$5,0.01)/0.4960)*(MAX(0.5700-Settings!$B$5,0.01)/0.5700)*(MAX(0.5000-Settings!$B$5,0.01)/0.5000) | D24: Aaron Rodgers (PIT) Pass Yds More 212.5 [50%] Denzel Boston (CLE) Receptions More 2.5 [57%] DK Metcalf (PIT) Rush+Rec Yds More 42.5 [50%] | E24: =$C24*E$19-1 | F24: =$C24*F$19-1 | G24: =$C24*G$19-1 | H24: =$C24*H$19-1 | I24: =$C24*I$19-1 | J24: =$C24*J$19-1 | K24: =$C24*K$19-1 | L24: =$C24*L$19-1 | ... S24: =$C24*S$19-1
A25: 6 | B25: =(1+$C$18)/C25 | C25: =0.18280*(MAX(0.5980-Settings!$B$5,0.01)/0.5980)*(MAX(0.5490-Settings!$B$5,0.01)/0.5490)*(MAX(0.5660-Settings!$B$5,0.01)/0.5660) | D25: Raheim Sanders (CLE) Receptions More 1.5 [60%] Pat Freiermuth (PIT) Receptions Less 3.5 [55%] Jerry Jeudy (CLE) Receptions Less 1.5 [57%] | E25: =$C25*E$19-1 | F25: =$C25*F$19-1 | G25: =$C25*G$19-1 | H25: =$C25*H$19-1 | I25: =$C25*I$19-1 | J25: =$C25*J$19-1 | K25: =$C25*K$19-1 | L25: =$C25*L$19-1 | ... S25: =$C25*S$19-1
A26: 7 | B26: =(1+$C$18)/C26 | C26: =0.18320*(MAX(0.4990-Settings!$B$5,0.01)/0.4990)*(MAX(0.5460-Settings!$B$5,0.01)/0.5460)*(MAX(0.5660-Settings!$B$5,0.01)/0.5660) | D26: Deshaun Watson (CLE) Pass Yds Less 187.5 [50%] Jaylen Warren (PIT) Receptions Less 3.5 [55%] Jerry Jeudy (CLE) Receptions Less 1.5 [57%] | E26: =$C26*E$19-1 | F26: =$C26*F$19-1 | G26: =$C26*G$19-1 | H26: =$C26*H$19-1 | I26: =$C26*I$19-1 | J26: =$C26*J$19-1 | K26: =$C26*K$19-1 | L26: =$C26*L$19-1 | ... S26: =$C26*S$19-1
A27: 8 | B27: =(1+$C$18)/C27 | C27: =0.18160*(MAX(0.5010-Settings!$B$5,0.01)/0.5010)*(MAX(0.5290-Settings!$B$5,0.01)/0.5290)*(MAX(0.5980-Settings!$B$5,0.01)/0.5980) | D27: Deshaun Watson (CLE) Pass Yds More 187.5 [50%] DK Metcalf (PIT) Receptions More 3.5 [53%] Raheim Sanders (CLE) Receptions More 1.5 [60%] | E27: =$C27*E$19-1 | F27: =$C27*F$19-1 | G27: =$C27*G$19-1 | H27: =$C27*H$19-1 | I27: =$C27*I$19-1 | J27: =$C27*J$19-1 | K27: =$C27*K$19-1 | L27: =$C27*L$19-1 | ... S27: =$C27*S$19-1
A28: 9 | B28: =(1+$C$18)/C28 | C28: =0.18040*(MAX(0.5010-Settings!$B$5,0.01)/0.5010)*(MAX(0.5700-Settings!$B$5,0.01)/0.5700)*(MAX(0.5490-Settings!$B$5,0.01)/0.5490) | D28: Deshaun Watson (CLE) Pass Yds More 187.5 [50%] Denzel Boston (CLE) Receptions More 2.5 [57%] Pat Freiermuth (PIT) Receptions Less 3.5 [55%] | E28: =$C28*E$19-1 | F28: =$C28*F$19-1 | G28: =$C28*G$19-1 | H28: =$C28*H$19-1 | I28: =$C28*I$19-1 | J28: =$C28*J$19-1 | K28: =$C28*K$19-1 | L28: =$C28*L$19-1 | ... S28: =$C28*S$19-1
A29: 10 | B29: =(1+$C$18)/C29 | C29: =0.17960*(MAX(0.5040-Settings!$B$5,0.01)/0.5040)*(MAX(0.5360-Settings!$B$5,0.01)/0.5360)*(MAX(0.5660-Settings!$B$5,0.01)/0.5660) | D29: Aaron Rodgers (PIT) Pass Yds Less 212.5 [50%] Michael Pittman Jr. (PIT) Receptions Less 3.5 [54%] Jerry Jeudy (CLE) Receptions Less 1.5 [57%] | E29: =$C29*E$19-1 | F29: =$C29*F$19-1 | G29: =$C29*G$19-1 | H29: =$C29*H$19-1 | I29: =$C29*I$19-1 | J29: =$C29*J$19-1 | K29: =$C29*K$19-1 | L29: =$C29*L$19-1 | ... S29: =$C29*S$19-1
A31: 4 LEGS | B31: Cushion | C31: =4*Settings!$B$6 | D31: 4-leg entries | multipliers 6.00x to 12.00x, every 0.25x
A32: # | B32: PLAY at | C32: All hit | D32: Entry (book lines) | E32: 6 | F32: 6.25 | G32: 6.5 | H32: 6.75 | I32: 7 | J32: 7.25 | K32: 7.5 | L32: 7.75 | M32: 8 | N32: 8.25 | O32: 8.5 | P32: 8.75 | Q32: 9 | R32: 9.25 | S32: 9.5 | T32: 9.75 | U32: 10 | V32: 10.25 | W32: 10.5 | X32: 10.75 | Y32: 11 | Z32: 11.25 | AA32: 11.5 | AB32: 11.75 | AC32: 12
A33: 1 | B33: =(1+$C$31)/C33 | C33: =0.11720*(MAX(0.5700-Settings!$B$5,0.01)/0.5700)*(MAX(0.5980-Settings!$B$5,0.01)/0.5980)*(MAX(0.5040-Settings!$B$5,0.01)/0.5040)*(MAX(0.5000-Settings!$B$5,0.01)/0.5000) | D33: Denzel Boston (CLE) Receptions More 2.5 [57%] Raheim Sanders (CLE) Receptions More 1.5 [60%] Aaron Rodgers (PIT) Pass Yds Less 212.5 [50%] DK Metcalf (PIT) Rush+Rec Yds Less 42.5 [50%] | E33: =$C33*E$32-1 | F33: =$C33*F$32-1 | G33: =$C33*G$32-1 | H33: =$C33*H$32-1 | I33: =$C33*I$32-1 | J33: =$C33*J$32-1 | K33: =$C33*K$32-1 | L33: =$C33*L$32-1 | ... AC33: =$C33*AC$32-1
A34: 2 | B34: =(1+$C$31)/C34 | C34: =0.11700*(MAX(0.4960-Settings!$B$5,0.01)/0.4960)*(MAX(0.5010-Settings!$B$5,0.01)/0.5010)*(MAX(0.5110-Settings!$B$5,0.01)/0.5110)*(MAX(0.5980-Settings!$B$5,0.01)/0.5980) | D34: Aaron Rodgers (PIT) Pass Yds More 212.5 [50%] Deshaun Watson (CLE) Pass Yds More 187.5 [50%] DK Metcalf (PIT) Rec Yds More 41.5 [51%] Raheim Sanders (CLE) Receptions More 1.5 [60%] | E34: =$C34*E$32-1 | F34: =$C34*F$32-1 | G34: =$C34*G$32-1 | H34: =$C34*H$32-1 | I34: =$C34*I$32-1 | J34: =$C34*J$32-1 | K34: =$C34*K$32-1 | L34: =$C34*L$32-1 | ... AC34: =$C34*AC$32-1
A35: 3 | B35: =(1+$C$31)/C35 | C35: =0.11590*(MAX(0.5010-Settings!$B$5,0.01)/0.5010)*(MAX(0.5290-Settings!$B$5,0.01)/0.5290)*(MAX(0.5700-Settings!$B$5,0.01)/0.5700)*(MAX(0.5980-Settings!$B$5,0.01)/0.5980) | D35: Deshaun Watson (CLE) Pass Yds More 187.5 [50%] DK Metcalf (PIT) Receptions More 3.5 [53%] Denzel Boston (CLE) Receptions More 2.5 [57%] Raheim Sanders (CLE) Receptions More 1.5 [60%] | E35: =$C35*E$32-1 | F35: =$C35*F$32-1 | G35: =$C35*G$32-1 | H35: =$C35*H$32-1 | I35: =$C35*I$32-1 | J35: =$C35*J$32-1 | K35: =$C35*K$32-1 | L35: =$C35*L$32-1 | ... AC35: =$C35*AC$32-1
A36: 4 | B36: =(1+$C$31)/C36 | C36: =0.11500*(MAX(0.5040-Settings!$B$5,0.01)/0.5040)*(MAX(0.4990-Settings!$B$5,0.01)/0.4990)*(MAX(0.5090-Settings!$B$5,0.01)/0.5090)*(MAX(0.5000-Settings!$B$5,0.01)/0.5000) | D36: Aaron Rodgers (PIT) Pass Yds Less 212.5 [50%] Deshaun Watson (CLE) Pass Yds Less 187.5 [50%] Denzel Boston (CLE) Rec Yds Less 37.5 [51%] DK Metcalf (PIT) Rush+Rec Yds Less 42.5 [50%] | E36: =$C36*E$32-1 | F36: =$C36*F$32-1 | G36: =$C36*G$32-1 | H36: =$C36*H$32-1 | I36: =$C36*I$32-1 | J36: =$C36*J$32-1 | K36: =$C36*K$32-1 | L36: =$C36*L$32-1 | ... AC36: =$C36*AC$32-1
A37: 5 | B37: =(1+$C$31)/C37 | C37: =0.11340*(MAX(0.4960-Settings!$B$5,0.01)/0.4960)*(MAX(0.5010-Settings!$B$5,0.01)/0.5010)*(MAX(0.5700-Settings!$B$5,0.01)/0.5700)*(MAX(0.5000-Settings!$B$5,0.01)/0.5000) | D37: Aaron Rodgers (PIT) Pass Yds More 212.5 [50%] Deshaun Watson (CLE) Pass Yds More 187.5 [50%] Denzel Boston (CLE) Receptions More 2.5 [57%] DK Metcalf (PIT) Rush+Rec Yds More 42.5 [50%] | E37: =$C37*E$32-1 | F37: =$C37*F$32-1 | G37: =$C37*G$32-1 | H37: =$C37*H$32-1 | I37: =$C37*I$32-1 | J37: =$C37*J$32-1 | K37: =$C37*K$32-1 | L37: =$C37*L$32-1 | ... AC37: =$C37*AC$32-1
A38: 6 | B38: =(1+$C$31)/C38 | C38: =0.11200*(MAX(0.5040-Settings!$B$5,0.01)/0.5040)*(MAX(0.4990-Settings!$B$5,0.01)/0.4990)*(MAX(0.4890-Settings!$B$5,0.01)/0.4890)*(MAX(0.4990-Settings!$B$5,0.01)/0.4990) | D38: Aaron Rodgers (PIT) Pass Yds Less 212.5 [50%] Deshaun Watson (CLE) Pass Yds Less 187.5 [50%] DK Metcalf (PIT) Rec Yds Less 41.5 [49%] Jerry Jeudy (CLE) Rec Yds Less 13.5 [50%] | E38: =$C38*E$32-1 | F38: =$C38*F$32-1 | G38: =$C38*G$32-1 | H38: =$C38*H$32-1 | I38: =$C38*I$32-1 | J38: =$C38*J$32-1 | K38: =$C38*K$32-1 | L38: =$C38*L$32-1 | ... AC38: =$C38*AC$32-1
A39: 7 | B39: =(1+$C$31)/C39 | C39: =0.11153*(MAX(0.5700-Settings!$B$5,0.01)/0.5700)*(MAX(0.5040-Settings!$B$5,0.01)/0.5040)*(MAX(0.5040-Settings!$B$5,0.01)/0.5040)*(MAX(0.5160-Settings!$B$5,0.01)/0.5160) | D39: Denzel Boston (CLE) Receptions More 2.5 [57%] Aaron Rodgers (PIT) Pass Yds Less 212.5 [50%] Michael Pittman Jr. (PIT) Rec Yds Less 34.5 [50%] Germie Bernard (PIT) Rec Yds Less 6.5 [52%] | E39: =$C39*E$32-1 | F39: =$C39*F$32-1 | G39: =$C39*G$32-1 | H39: =$C39*H$32-1 | I39: =$C39*I$32-1 | J39: =$C39*J$32-1 | K39: =$C39*K$32-1 | L39: =$C39*L$32-1 | ... AC39: =$C39*AC$32-1
A40: 8 | B40: =(1+$C$31)/C40 | C40: =0.11096*(MAX(0.5010-Settings!$B$5,0.01)/0.5010)*(MAX(0.4910-Settings!$B$5,0.01)/0.4910)*(MAX(0.5980-Settings!$B$5,0.01)/0.5980)*(MAX(0.5490-Settings!$B$5,0.01)/0.5490) | D40: Deshaun Watson (CLE) Pass Yds More 187.5 [50%] Denzel Boston (CLE) Rec Yds More 37.5 [49%] Raheim Sanders (CLE) Receptions More 1.5 [60%] Pat Freiermuth (PIT) Receptions Less 3.5 [55%] | E40: =$C40*E$32-1 | F40: =$C40*F$32-1 | G40: =$C40*G$32-1 | H40: =$C40*H$32-1 | I40: =$C40*I$32-1 | J40: =$C40*J$32-1 | K40: =$C40*K$32-1 | L40: =$C40*L$32-1 | ... AC40: =$C40*AC$32-1
A41: 9 | B41: =(1+$C$31)/C41 | C41: =0.11039*(MAX(0.5040-Settings!$B$5,0.01)/0.5040)*(MAX(0.5490-Settings!$B$5,0.01)/0.5490)*(MAX(0.5660-Settings!$B$5,0.01)/0.5660)*(MAX(0.5000-Settings!$B$5,0.01)/0.5000) | D41: Aaron Rodgers (PIT) Pass Yds Less 212.5 [50%] Pat Freiermuth (PIT) Receptions Less 3.5 [55%] Jerry Jeudy (CLE) Receptions Less 1.5 [57%] DK Metcalf (PIT) Rush+Rec Yds Less 42.5 [50%] | E41: =$C41*E$32-1 | F41: =$C41*F$32-1 | G41: =$C41*G$32-1 | H41: =$C41*H$32-1 | I41: =$C41*I$32-1 | J41: =$C41*J$32-1 | K41: =$C41*K$32-1 | L41: =$C41*L$32-1 | ... AC41: =$C41*AC$32-1
A42: 10 | B42: =(1+$C$31)/C42 | C42: =0.11040*(MAX(0.4960-Settings!$B$5,0.01)/0.4960)*(MAX(0.5110-Settings!$B$5,0.01)/0.5110)*(MAX(0.4990-Settings!$B$5,0.01)/0.4990)*(MAX(0.5090-Settings!$B$5,0.01)/0.5090) | D42: Aaron Rodgers (PIT) Pass Yds More 212.5 [50%] DK Metcalf (PIT) Rec Yds More 41.5 [51%] Deshaun Watson (CLE) Pass Yds Less 187.5 [50%] Denzel Boston (CLE) Rec Yds Less 37.5 [51%] | E42: =$C42*E$32-1 | F42: =$C42*F$32-1 | G42: =$C42*G$32-1 | H42: =$C42*H$32-1 | I42: =$C42*I$32-1 | J42: =$C42*J$32-1 | K42: =$C42*K$32-1 | L42: =$C42*L$32-1 | ... AC42: =$C42*AC$32-1
A44: 5 LEGS | B44: Cushion | C44: =5*Settings!$B$6 | D44: 5-leg entries | multipliers 12.00x to 25.00x, every 0.5x
...

Sheet Top Entries
A1: Top Entries
A2: Best combinations at the book lines, at STANDARD payouts. Before playing, rebuild the one you like in the Entry Builder with the app multiplier and PrizePicks lines.
A4: Legs | B4: All hit | C4: Standard payout | D4: EV | E4: Cushion | F4: Clears it? | G4: Leg 1 | H4: Leg 2 | I4: Leg 3 | J4: Leg 4 | K4: Leg 5 | L4: Leg 6
A5: 2 | B5: 0.3274 | C5: =INDEX(Settings!$B$11:$B$15,MATCH(A5,Settings!$A$11:$A$15,0)) | D5: =B5*C5-1 | E5: =A5*Settings!$B$6 | F5: =IF(D5>=E5,"Yes","No") | G5: Raheim Sanders (CLE) - Receptions More 1.5 [60%] | H5: Pat Freiermuth (PIT) - Receptions Less 3.5 [55%]
A6: 2 | B6: 0.32539999 | C6: =INDEX(Settings!$B$11:$B$15,MATCH(A6,Settings!$A$11:$A$15,0)) | D6: =B6*C6-1 | E6: =A6*Settings!$B$6 | F6: =IF(D6>=E6,"Yes","No") | G6: Raheim Sanders (CLE) - Receptions More 1.5 [60%] | H6: Jaylen Warren (PIT) - Receptions Less 3.5 [55%]
A7: 2 | B7: 0.32440001 | C7: =INDEX(Settings!$B$11:$B$15,MATCH(A7,Settings!$A$11:$A$15,0)) | D7: =B7*C7-1 | E7: =A7*Settings!$B$6 | F7: =IF(D7>=E7,"Yes","No") | G7: DK Metcalf (PIT) - Receptions More 3.5 [53%] | H7: Raheim Sanders (CLE) - Receptions More 1.5 [60%]
A8: 2 | B8: 0.31760001 | C8: =INDEX(Settings!$B$11:$B$15,MATCH(A8,Settings!$A$11:$A$15,0)) | D8: =B8*C8-1 | E8: =A8*Settings!$B$6 | F8: =IF(D8>=E8,"Yes","No") | G8: Pat Freiermuth (PIT) - Receptions Less 3.5 [55%] | H8: Jerry Jeudy (CLE) - Receptions Less 1.5 [57%]
A9: 2 | B9: 0.3152 | C9: =INDEX(Settings!$B$11:$B$15,MATCH(A9,Settings!$A$11:$A$15,0)) | D9: =B9*C9-1 | E9: =A9*Settings!$B$6 | F9: =IF(D9>=E9,"Yes","No") | G9: Denzel Boston (CLE) - Receptions More 2.5 [57%] | H9: Jaylen Warren (PIT) - Receptions Less 3.5 [55%]
A11: 3 | B11: 0.19679999 | C11: =INDEX(Settings!$B$11:$B$15,MATCH(A11,Settings!$A$11:$A$15,0)) | D11: =B11*C11-1 | E11: =A11*Settings!$B$6 | F11: =IF(D11>=E11,"Yes","No") | G11: Denzel Boston (CLE) - Receptions More 2.5 [57%] | H11: Raheim Sanders (CLE) - Receptions More 1.5 [60%] | I11: Jaylen Warren (PIT) - Receptions Less 3.5 [55%]
A12: 3 | B12: 0.1954 | C12: =INDEX(Settings!$B$11:$B$15,MATCH(A12,Settings!$A$11:$A$15,0)) | D12: =B12*C12-1 | E12: =A12*Settings!$B$6 | F12: =IF(D12>=E12,"Yes","No") | G12: Aaron Rodgers (PIT) - Pass Yds More 212.5 [50%] | H12: DK Metcalf (PIT) - Rec Yds More 41.5 [51%] | I12: Raheim Sanders (CLE) - Receptions More 1.5 [60%]
A13: 3 | B13: 0.1926 | C13: =INDEX(Settings!$B$11:$B$15,MATCH(A13,Settings!$A$11:$A$15,0)) | D13: =B13*C13-1 | E13: =A13*Settings!$B$6 | F13: =IF(D13>=E13,"Yes","No") | G13: Raheim Sanders (CLE) - Receptions More 1.5 [60%] | H13: Aaron Rodgers (PIT) - Pass Yds Less 212.5 [50%] | I13: DK Metcalf (PIT) - Rush+Rec Yds Less 42.5 [50%]
A14: 3 | B14: 0.18440001 | C14: =INDEX(Settings!$B$11:$B$15,MATCH(A14,Settings!$A$11:$A$15,0)) | D14: =B14*C14-1 | E14: =A14*Settings!$B$6 | F14: =IF(D14>=E14,"Yes","No") | G14: Denzel Boston (CLE) - Receptions More 2.5 [57%] | H14: Aaron Rodgers (PIT) - Pass Yds Less 212.5 [50%] | I14: DK Metcalf (PIT) - Rec Yds Less 41.5 [49%]
A15: 3 | B15: 0.1842 | C15: =INDEX(Settings!$B$11:$B$15,MATCH(A15,Settings!$A$11:$A$15,0)) | D15: =B15*C15-1 | E15: =A15*Settings!$B$6 | F15: =IF(D15>=E15,"Yes","No") | G15: Aaron Rodgers (PIT) - Pass Yds More 212.5 [50%] | H15: Denzel Boston (CLE) - Receptions More 2.5 [57%] | I15: DK Metcalf (PIT) - Rush+Rec Yds More 42.5 [50%]
A17: 4 | B17: 0.1172 | C17: =INDEX(Settings!$B$11:$B$15,MATCH(A17,Settings!$A$11:$A$15,0)) | D17: =B17*C17-1 | E17: =A17*Settings!$B$6 | F17: =IF(D17>=E17,"Yes","No") | G17: Denzel Boston (CLE) - Receptions More 2.5 [57%] | H17: Raheim Sanders (CLE) - Receptions More 1.5 [60%] | I17: Aaron Rodgers (PIT) - Pass Yds Less 212.5 [50%] | J17: DK Metcalf (PIT) - Rush+Rec Yds Less 42.5 [50%]
A18: 4 | B18: 0.117 | C18: =INDEX(Settings!$B$11:$B$15,MATCH(A18,Settings!$A$11:$A$15,0)) | D18: =B18*C18-1 | E18: =A18*Settings!$B$6 | F18: =IF(D18>=E18,"Yes","No") | G18: Aaron Rodgers (PIT) - Pass Yds More 212.5 [50%] | H18: Deshaun Watson (CLE) - Pass Yds More 187.5 [50%] | I18: DK Metcalf (PIT) - Rec Yds More 41.5 [51%] | J18: Raheim Sanders (CLE) - Receptions More 1.5 [60%]
A19: 4 | B19: 0.1159 | C19: =INDEX(Settings!$B$11:$B$15,MATCH(A19,Settings!$A$11:$A$15,0)) | D19: =B19*C19-1 | E19: =A19*Settings!$B$6 | F19: =IF(D19>=E19,"Yes","No") | G19: Deshaun Watson (CLE) - Pass Yds More 187.5 [50%] | H19: DK Metcalf (PIT) - Receptions More 3.5 [53%] | I19: Denzel Boston (CLE) - Receptions More 2.5 [57%] | J19: Raheim Sanders (CLE) - Receptions More 1.5 [60%]
A20: 4 | B20: 0.115 | C20: =INDEX(Settings!$B$11:$B$15,MATCH(A20,Settings!$A$11:$A$15,0)) | D20: =B20*C20-1 | E20: =A20*Settings!$B$6 | F20: =IF(D20>=E20,"Yes","No") | G20: Aaron Rodgers (PIT) - Pass Yds Less 212.5 [50%] | H20: Deshaun Watson (CLE) - Pass Yds Less 187.5 [50%] | I20: Denzel Boston (CLE) - Rec Yds Less 37.5 [51%] | J20: DK Metcalf (PIT) - Rush+Rec Yds Less 42.5 [50%]
A21: 4 | B21: 0.1134 | C21: =INDEX(Settings!$B$11:$B$15,MATCH(A21,Settings!$A$11:$A$15,0)) | D21: =B21*C21-1 | E21: =A21*Settings!$B$6 | F21: =IF(D21>=E21,"Yes","No") | G21: Aaron Rodgers (PIT) - Pass Yds More 212.5 [50%] | H21: Deshaun Watson (CLE) - Pass Yds More 187.5 [50%] | I21: Denzel Boston (CLE) - Receptions More 2.5 [57%] | J21: DK Metcalf (PIT) - Rush+Rec Yds More 42.5 [50%]
A23: 5 | B23: 0.073720001 | C23: =INDEX(Settings!$B$11:$B$15,MATCH(A23,Settings!$A$11:$A$15,0)) | D23: =B23*C23-1 | E23: =A23*Settings!$B$6 | F23: =IF(D23>=E23,"Yes","No") | G23: Aaron Rodgers (PIT) - Pass Yds More 212.5 [50%] | H23: Deshaun Watson (CLE) - Pass Yds More 187.5 [50%] | I23: DK Metcalf (PIT) - Rec Yds More 41.5 [51%] | J23: Denzel Boston (CLE) - Receptions More 2.5 [57%] | K23: Raheim Sanders (CLE) - Receptions More 1.5 [60%]
A24: 5 | B24: 0.07068 | C24: =INDEX(Settings!$B$11:$B$15,MATCH(A24,Settings!$A$11:$A$15,0)) | D24: =B24*C24-1 | E24: =A24*Settings!$B$6 | F24: =IF(D24>=E24,"Yes","No") | G24: Aaron Rodgers (PIT) - Pass Yds More 212.5 [50%] | H24: Deshaun Watson (CLE) - Pass Yds More 187.5 [50%] | I24: Jerry Jeudy (CLE) - Rec Yds More 13.5 [50%] | J24: DK Metcalf (PIT) - Rush+Rec Yds More 42.5 [50%] | K24: Raheim Sanders (CLE) - Receptions More 1.5 [60%]
A25: 5 | B25: 0.070109993 | C25: =INDEX(Settings!$B$11:$B$15,MATCH(A25,Settings!$A$11:$A$15,0)) | D25: =B25*C25-1 | E25: =A25*Settings!$B$6 | F25: =IF(D25>=E25,"Yes","No") | G25: Aaron Rodgers (PIT) - Pass Yds Less 212.5 [50%] | H25: Deshaun Watson (CLE) - Pass Yds Less 187.5 [50%] | I25: Denzel Boston (CLE) - Rec Yds Less 37.5 [51%] | J25: DK Metcalf (PIT) - Rush+Rec Yds Less 42.5 [50%] | K25: Jerry Jeudy (CLE) - Rush+Rec Yds Less 15.5 [50%]
A26: 5 | B26: 0.069920003 | C26: =INDEX(Settings!$B$11:$B$15,MATCH(A26,Settings!$A$11:$A$15,0)) | D26: =B26*C26-1 | E26: =A26*Settings!$B$6 | F26: =IF(D26>=E26,"Yes","No") | G26: Denzel Boston (CLE) - Receptions More 2.5 [57%] | H26: Raheim Sanders (CLE) - Receptions More 1.5 [60%] | I26: Aaron Rodgers (PIT) - Pass Yds Less 212.5 [50%] | J26: Michael Pittman Jr. (PIT) - Rec Yds Less 34.5 [50%] | K26: DK Metcalf (PIT) - Rush+Rec Yds Less 42.5 [50%]
A27: 5 | B27: 0.069729999 | C27: =INDEX(Settings!$B$11:$B$15,MATCH(A27,Settings!$A$11:$A$15,0)) | D27: =B27*C27-1 | E27: =A27*Settings!$B$6 | F27: =IF(D27>=E27,"Yes","No") | G27: Denzel Boston (CLE) - Receptions More 2.5 [57%] | H27: Raheim Sanders (CLE) - Receptions More 1.5 [60%] | I27: Aaron Rodgers (PIT) - Pass Yds Less 212.5 [50%] | J27: Jaylen Warren (PIT) - Receptions Less 3.5 [55%] | K27: Germie Bernard (PIT) - Rec Yds Less 6.5 [52%]
A29: 6 | B29: 0.043739997 | C29: =INDEX(Settings!$B$11:$B$15,MATCH(A29,Settings!$A$11:$A$15,0)) | D29: =B29*C29-1 | E29: =A29*Settings!$B$6 | F29: =IF(D29>=E29,"Yes","No") | G29: Aaron Rodgers (PIT) - Pass Yds More 212.5 [50%] | H29: Deshaun Watson (CLE) - Pass Yds More 187.5 [50%] | I29: DK Metcalf (PIT) - Rec Yds More 41.5 [51%] | J29: Harold Fannin Jr. (CLE) - Rec Yds More 40.5 [49%] | K29: Denzel Boston (CLE) - Receptions More 2.5 [57%] | L29: Raheim Sanders (CLE) - Receptions More 1.5 [60%]
A30: 6 | B30: 0.042959001 | C30: =INDEX(Settings!$B$11:$B$15,MATCH(A30,Settings!$A$11:$A$15,0)) | D30: =B30*C30-1 | E30: =A30*Settings!$B$6 | F30: =IF(D30>=E30,"Yes","No") | G30: Aaron Rodgers (PIT) - Pass Yds More 212.5 [50%] | H30: Deshaun Watson (CLE) - Pass Yds More 187.5 [50%] | I30: DK Metcalf (PIT) - Rec Yds More 41.5 [51%] | J30: Darnell Washington (PIT) - Rec Yds More 16.5 [52%] | K30: Jerry Jeudy (CLE) - Rec Yds More 13.5 [50%] | L30: Raheim Sanders (CLE) - Receptions More 1.5 [60%]
A31: 6 | B31: 0.042660002 | C31: =INDEX(Settings!$B$11:$B$15,MATCH(A31,Settings!$A$11:$A$15,0)) | D31: =B31*C31-1 | E31: =A31*Settings!$B$6 | F31: =IF(D31>=E31,"Yes","No") | G31: Aaron Rodgers (PIT) - Pass Yds More 212.5 [50%] | H31: Deshaun Watson (CLE) - Pass Yds More 187.5 [50%] | I31: Denzel Boston (CLE) - Receptions More 2.5 [57%] | J31: Jerry Jeudy (CLE) - Rec Yds More 13.5 [50%] | K31: Michael Pittman Jr. (PIT) - Rush+Rec Yds More 32.5 [50%] | L31: Raheim Sanders (CLE) - Receptions More 1.5 [60%]
A32: 6 | B32: 0.04194 | C32: =INDEX(Settings!$B$11:$B$15,MATCH(A32,Settings!$A$11:$A$15,0)) | D32: =B32*C32-1 | E32: =A32*Settings!$B$6 | F32: =IF(D32>=E32,"Yes","No") | G32: Denzel Boston (CLE) - Receptions More 2.5 [57%] | H32: Raheim Sanders (CLE) - Receptions More 1.5 [60%] | I32: Aaron Rodgers (PIT) - Pass Yds Less 212.5 [50%] | J32: Jaylen Warren (PIT) - Receptions Less 3.5 [55%] | K32: DK Metcalf (PIT) - Rush+Rec Yds Less 42.5 [50%] | L32: Germie Bernard (PIT) - Rec Yds Less 6.5 [52%]
A33: 6 | B33: 0.041515 | C33: =INDEX(Settings!$B$11:$B$15,MATCH(A33,Settings!$A$11:$A$15,0)) | D33: =B33*C33-1 | E33: =A33*Settings!$B$6 | F33: =IF(D33>=E33,"Yes","No") | G33: Aaron Rodgers (PIT) - Pass Yds More 212.5 [50%] | H33: Deshaun Watson (CLE) - Pass Yds More 187.5 [50%] | I33: Darnell Washington (PIT) - Rec Yds More 16.5 [52%] | J33: DK Metcalf (PIT) - Rush+Rec Yds More 42.5 [50%] | K33: Jerry Jeudy (CLE) - Rush+Rec Yds More 15.5 [50%] | L33: Raheim Sanders (CLE) - Receptions More 1.5 [60%]

Sheet Best Legs
A1: Best Legs
A2: Strongest picks within 2 steps of the book line (the lines PrizePicks usually posts). TD Less is left out - PrizePicks only offers More. Use the filter arrows.
A4: Confidence | B4: Pick | C4: Player | D4: Team | E4: Stat | F4: Book line | G4: Steps from book | H4: Game
A5: 0.959 | B5: Less 3.5 | C5: Jerry Jeudy | D5: CLE | E5: Receptions | F5: 1.5 | G5: 2 | H5: PIT @ CLE
A6: 0.942 | B6: Less 3.5 | C6: Aaron Rodgers | D6: PIT | E6: Pass TDs | F6: 1.5 | G6: 2 | H6: PIT @ CLE
A7: 0.914 | B7: More 0.5 | C7: Denzel Boston | D7: CLE | E7: Receptions | F7: 2.5 | G7: -2 | H7: PIT @ CLE
A8: 0.897 | B8: Less 49.5 | C8: Travis Homer | D8: PIT | E8: Rush Yds | F8: 39.5 | G8: 2 | H8: PIT @ CLE
A9: 0.888 | B9: Less 4.5 | C9: Roman Wilson | D9: PIT | E9: Receptions | F9: 2.5 | G9: 2 | H9: PIT @ CLE
A10: 0.886 | B10: Less 2.5 | C10: Deshaun Watson | D10: CLE | E10: Pass TDs | F10: 0.5 | G10: 2 | H10: PIT @ CLE
A11: 0.879 | B11: Less 44.5 | C11: Travis Homer | D11: PIT | E11: Rush Yds | F11: 39.5 | G11: 1 | H11: PIT @ CLE
A12: 0.874 | B12: Less 4.5 | C12: Quinshon Judkins | D12: CLE | E12: Receptions | F12: 2.5 | G12: 2 | H12: PIT @ CLE
A13: 0.854 | B13: More 1.5 | C13: DK Metcalf | D13: PIT | E13: Receptions | F13: 3.5 | G13: -2 | H13: PIT @ CLE
A14: 0.848 | B14: Less 2.5 | C14: Jerry Jeudy | D14: CLE | E14: Receptions | F14: 1.5 | G14: 1 | H14: PIT @ CLE
A15: 0.844 | B15: Less 2.5 | C15: Aaron Rodgers | D15: PIT | E15: Pass TDs | F15: 1.5 | G15: 1 | H15: PIT @ CLE
A16: 0.841 | B16: More 0.5 | C16: Roman Wilson | D16: PIT | E16: Receptions | F16: 2.5 | G16: -2 | H16: PIT @ CLE
... A201: 0.5 | B201: Less 36.5 | C201: Denzel Boston | D201: CLE | E201: Rush+Rec Yds | F201: 36.5 | G201: 0 | H201: PIT @ CLE

Sheet Player Lines
A1: Player Lines
A2: Every line we priced for every player: filter Player and Stat to see his full ladder. 'Pick' is the side more likely to hit at that line.
A4: Player | B4: Team | C4: Stat | D4: Line | E4: Pick | F4: Confidence | G4: Book line | H4: Steps from book | I4: Game
A5: Aaron Rodgers | B5: PIT | C5: Anytime TDs | D5: 0.5 | E5: Less | F5: 0.933 | G5: 0.5 | H5: 0 | I5: PIT @ CLE
A6: Aaron Rodgers | B6: PIT | C6: Pass TDs | D6: 0.5 | E6: More | F6: 0.7 | G6: 1.5 | H6: -1 | I6: PIT @ CLE
A7: Aaron Rodgers | B7: PIT | C7: Pass TDs | D7: 1.5 | E7: Less | F7: 0.639 | G7: 1.5 | H7: 0 | I7: PIT @ CLE
A8: Aaron Rodgers | B8: PIT | C8: Pass TDs | D8: 2.5 | E8: Less | F8: 0.844 | G8: 1.5 | H8: 1 | I8: PIT @ CLE
A9: Aaron Rodgers | B9: PIT | C9: Pass TDs | D9: 3.5 | E9: Less | F9: 0.942 | G9: 1.5 | H9: 2 | I9: PIT @ CLE
A10: Aaron Rodgers | B10: PIT | C10: Pass Yds | D10: 112.5 | E10: More | F10: 0.953 | G10: 212.5 | H10: -10 | I10: PIT @ CLE
A11: Aaron Rodgers | B11: PIT | C11: Pass Yds | D11: 122.5 | E11: More | F11: 0.93 | G11: 212.5 | H11: -9 | I11: PIT @ CLE
A12: Aaron Rodgers | B12: PIT | C12: Pass Yds | D12: 132.5 | E12: More | F12: 0.905 | G12: 212.5 | H12: -8 | I12: PIT @ CLE
A13: Aaron Rodgers | B13: PIT | C13: Pass Yds | D13: 142.5 | E13: More | F13: 0.872 | G13: 212.5 | H13: -7 | I13: PIT @ CLE
A14: Aaron Rodgers | B14: PIT | C14: Pass Yds | D14: 152.5 | E14: More | F14: 0.829 | G14: 212.5 | H14: -6 | I14: PIT @ CLE
A15: Aaron Rodgers | B15: PIT | C15: Pass Yds | D15: 162.5 | E15: More | F15: 0.777 | G15: 212.5 | H15: -5 | I15: PIT @ CLE
A16: Aaron Rodgers | B16: PIT | C16: Pass Yds | D16: 172.5 | E16: More | F16: 0.728 | G16: 212.5 | H16: -4 | I16: PIT @ CLE
... A622: Tylan Wallace | B622: CLE | C622: Anytime TDs | D622: 0.5 | E622: Less | F622: 0.959 | G622: 0.5 | H622: 0 | I622: PIT @ CLE

Sheet Injuries & Notes
A1: Injuries & Notes
A3: HANDLED IN THE MODEL (confirmed out - their work was given to teammates)
A4: Team | B4: Player | C4: Share removed | D4: Of team | E4: Status
A5: PIT | B5: Rico Dowdle | C5: 0.28 | D5: carries | E5: OUT - confirmed
A6: PIT | B6: Rico Dowdle | C6: 0.095 | D6: targets | E6: OUT - confirmed
A8: OTHER NEWS (not changed in the model)
A9: Team | B9: Player | C9: Status | D9: Note
A10: CLE | B10: KC Concepcion | C10: Not out | D10: Healthy and practicing; no lines in our odds feed, so not in this report. His targets were NOT given away.
A11: CLE | B11: Tylan Wallace | C11: Not official | D11: Knee, no practice all week. Only a 4% TD line; check inactives ~6:45 PM ET.
A12: PIT | B12: Joey Porter Jr. | C12: Out (traded to DAL) | D12: CB. Reported traded to Dallas Wednesday night. Defense changes are already in the sportsbook lines.
A13: PIT | B13: Jalen Ramsey / Brandin Echols | C13: Questionable | D13: CBs. If Ramsey sits, expect Cleveland passing lines to rise.
A14: CLE | B14: Elgton Jenkins | C14: Out | D14: Starting center; Luke Wypler starts. Already in the sportsbook lines.
A16: ABOUT THIS MODEL
A17: - Each player's chance at the book line comes from the sportsbooks (odds with their margin removed). The model adds the shape of each range and how legs move together.
A18: - Correlations were tuned on 206 past games; stacks of QB + 2 or more of his receivers are scaled down 5-10% because the model still slightly overrates them.
A19: - Yardage ranges are 5% narrower around the book line after testing on Week 3 sportsbook lines (results landed 51.5% in the middle 50%, 78.9% in the middle 80%).
A20: - Anytime TD chances come from four major books. The model's own "2+ TDs" numbers are not reliable - ignore them.
A21: - PrizePicks lines can differ from the book line. Always pick or type the PrizePicks line in the Entry Builder.

Sheet Learn the Math
A1: Learn the Math
A3: THE FORMULAS
A4: 1. Chance an entry hits = multiply the legs (55% x 55% = 30%). Legs from the same game that move together hit more often - the Entry Builder handles that.
A5: 2. Break-even = 1 / payout. A 5.25x payout needs the entry to hit 19.0% of the time.
A6: 3. EV (expected profit per $1) = chance it hits x payout - 1. Quick version: chance / break-even - 1.
A7: 4. Only bet with a cushion: at least +5% EV per live leg (Settings).
A8: 5. Stake = bankroll x 1/4 x EV / (payout - 1). Big EV does not mean bet big - big entries lose most nights.
A9: 6. Lift: 1.00 = legs unrelated, above 1 = they tend to hit together, below 1 = they get in each other's way.
A11: CHEAT SHEET - EV IF EVERY LEG HITS THE SAME % (standard payouts from Settings)
A12: Each leg hits | B12: 2-leg Power | C12: 3-leg Power | D12: 3-leg Flex | E12: 4-leg Power | F12: 4-leg Flex | G12: 5-leg Power | H12: 5-leg Flex | I12: 6-leg Power | J12: 6-leg Flex
A13: 0.5 | B13: =$A13^2*INDEX(Settings!$B$11:$B$15,MATCH(2,Settings!$A$11:$A$15,0))-1 | C13: =$A13^3*INDEX(Settings!$B$11:$B$15,MATCH(3,Settings!$A$11:$A$15,0))-1 | D13: =$A13^3*INDEX(Settings!$C$11:$C$15,MATCH(3,Settings!$A$11:$A$15,0))+3*$A13^2*(1-$A13)*INDEX(Settings!$D$11:$D$15,MATCH(3,Settings!$A$11:$A$15,0))+3*$A13^1*(1-$A13)^2*INDEX(Settings!$E$11:$E$15,MATCH(3,Settings!$A$11:$A$15,0))-1 | E13: =$A13^4*INDEX(Settings!$B$11:$B$15,MATCH(4,Settings!$A$11:$A$15,0))-1 | F13: =$A13^4*INDEX(Settings!$C$11:$C$15,MATCH(4,Settings!$A$11:$A$15,0))+4*$A13^3*(1-$A13)*INDEX(Settings!$D$11:$D$15,MATCH(4,Settings!$A$11:$A$15,0))+6*$A13^2*(1-$A13)^2*INDEX(Settings!$E$11:$E$15,MATCH(4,Settings!$A$11:$A$15,0))-1 | G13: =$A13^5*INDEX(Settings!$B$11:$B$15,MATCH(5,Settings!$A$11:$A$15,0))-1 | H13: =$A13^5*INDEX(Settings!$C$11:$C$15,MATCH(5,Settings!$A$11:$A$15,0))+5*$A13^4*(1-$A13)*INDEX(Settings!$D$11:$D$15,MATCH(5,Settings!$A$11:$A$15,0))+10*$A13^3*(1-$A13)^2*INDEX(Settings!$E$11:$E$15,MATCH(5,Settings!$A$11:$A$15,0))-1 | I13: =$A13^6*INDEX(Settings!$B$11:$B$15,MATCH(6,Settings!$A$11:$A$15,0))-1 | J13: =$A13^6*INDEX(Settings!$C$11:$C$15,MATCH(6,Settings!$A$11:$A$15,0))+6*$A13^5*(1-$A13)*INDEX(Settings!$D$11:$D$15,MATCH(6,Settings!$A$11:$A$15,0))+15*$A13^4*(1-$A13)^2*INDEX(Settings!$E$11:$E$15,MATCH(6,Settings!$A$11:$A$15,0))-1
A14: 0.51 | B14: =$A14^2*INDEX(Settings!$B$11:$B$15,MATCH(2,Settings!$A$11:$A$15,0))-1 | C14: =$A14^3*INDEX(Settings!$B$11:$B$15,MATCH(3,Settings!$A$11:$A$15,0))-1 | D14: =$A14^3*INDEX(Settings!$C$11:$C$15,MATCH(3,Settings!$A$11:$A$15,0))+3*$A14^2*(1-$A14)*INDEX(Settings!$D$11:$D$15,MATCH(3,Settings!$A$11:$A$15,0))+3*$A14^1*(1-$A14)^2*INDEX(Settings!$E$11:$E$15,MATCH(3,Settings!$A$11:$A$15,0))-1 | E14: =$A14^4*INDEX(Settings!$B$11:$B$15,MATCH(4,Settings!$A$11:$A$15,0))-1 | F14: =$A14^4*INDEX(Settings!$C$11:$C$15,MATCH(4,Settings!$A$11:$A$15,0))+4*$A14^3*(1-$A14)*INDEX(Settings!$D$11:$D$15,MATCH(4,Settings!$A$11:$A$15,0))+6*$A14^2*(1-$A14)^2*INDEX(Settings!$E$11:$E$15,MATCH(4,Settings!$A$11:$A$15,0))-1 | G14: =$A14^5*INDEX(Settings!$B$11:$B$15,MATCH(5,Settings!$A$11:$A$15,0))-1 | H14: =$A14^5*INDEX(Settings!$C$11:$C$15,MATCH(5,Settings!$A$11:$A$15,0))+5*$A14^4*(1-$A14)*INDEX(Settings!$D$11:$D$15,MATCH(5,Settings!$A$11:$A$15,0))+10*$A14^3*(1-$A14)^2*INDEX(Settings!$E$11:$E$15,MATCH(5,Settings!$A$11:$A$15,0))-1 | I14: =$A14^6*INDEX(Settings!$B$11:$B$15,MATCH(6,Settings!$A$11:$A$15,0))-1 | J14: =$A14^6*INDEX(Settings!$C$11:$C$15,MATCH(6,Settings!$A$11:$A$15,0))+6*$A14^5*(1-$A14)*INDEX(Settings!$D$11:$D$15,MATCH(6,Settings!$A$11:$A$15,0))+15*$A14^4*(1-$A14)^2*INDEX(Settings!$E$11:$E$15,MATCH(6,Settings!$A$11:$A$15,0))-1
A15: 0.52 | B15: =$A15^2*INDEX(Settings!$B$11:$B$15,MATCH(2,Settings!$A$11:$A$15,0))-1 | C15: =$A15^3*INDEX(Settings!$B$11:$B$15,MATCH(3,Settings!$A$11:$A$15,0))-1 | D15: =$A15^3*INDEX(Settings!$C$11:$C$15,MATCH(3,Settings!$A$11:$A$15,0))+3*$A15^2*(1-$A15)*INDEX(Settings!$D$11:$D$15,MATCH(3,Settings!$A$11:$A$15,0))+3*$A15^1*(1-$A15)^2*INDEX(Settings!$E$11:$E$15,MATCH(3,Settings!$A$11:$A$15,0))-1 | E15: =$A15^4*INDEX(Settings!$B$11:$B$15,MATCH(4,Settings!$A$11:$A$15,0))-1 | F15: =$A15^4*INDEX(Settings!$C$11:$C$15,MATCH(4,Settings!$A$11:$A$15,0))+4*$A15^3*(1-$A15)*INDEX(Settings!$D$11:$D$15,MATCH(4,Settings!$A$11:$A$15,0))+6*$A15^2*(1-$A15)^2*INDEX(Settings!$E$11:$E$15,MATCH(4,Settings!$A$11:$A$15,0))-1 | G15: =$A15^5*INDEX(Settings!$B$11:$B$15,MATCH(5,Settings!$A$11:$A$15,0))-1 | H15: =$A15^5*INDEX(Settings!$C$11:$C$15,MATCH(5,Settings!$A$11:$A$15,0))+5*$A15^4*(1-$A15)*INDEX(Settings!$D$11:$D$15,MATCH(5,Settings!$A$11:$A$15,0))+10*$A15^3*(1-$A15)^2*INDEX(Settings!$E$11:$E$15,MATCH(5,Settings!$A$11:$A$15,0))-1 | I15: =$A15^6*INDEX(Settings!$B$11:$B$15,MATCH(6,Settings!$A$11:$A$15,0))-1 | J15: =$A15^6*INDEX(Settings!$C$11:$C$15,MATCH(6,Settings!$A$11:$A$15,0))+6*$A15^5*(1-$A15)*INDEX(Settings!$D$11:$D$15,MATCH(6,Settings!$A$11:$A$15,0))+15*$A15^4*(1-$A15)^2*INDEX(Settings!$E$11:$E$15,MATCH(6,Settings!$A$11:$A$15,0))-1
A16: 0.53 | B16: =$A16^2*INDEX(Settings!$B$11:$B$15,MATCH(2,Settings!$A$11:$A$15,0))-1 | C16: =$A16^3*INDEX(Settings!$B$11:$B$15,MATCH(3,Settings!$A$11:$A$15,0))-1 | D16: =$A16^3*INDEX(Settings!$C$11:$C$15,MATCH(3,Settings!$A$11:$A$15,0))+3*$A16^2*(1-$A16)*INDEX(Settings!$D$11:$D$15,MATCH(3,Settings!$A$11:$A$15,0))+3*$A16^1*(1-$A16)^2*INDEX(Settings!$E$11:$E$15,MATCH(3,Settings!$A$11:$A$15,0))-1 | E16: =$A16^4*INDEX(Settings!$B$11:$B$15,MATCH(4,Settings!$A$11:$A$15,0))-1 | F16: =$A16^4*INDEX(Settings!$C$11:$C$15,MATCH(4,Settings!$A$11:$A$15,0))+4*$A16^3*(1-$A16)*INDEX(Settings!$D$11:$D$15,MATCH(4,Settings!$A$11:$A$15,0))+6*$A16^2*(1-$A16)^2*INDEX(Settings!$E$11:$E$15,MATCH(4,Settings!$A$11:$A$15,0))-1 | G16: =$A16^5*INDEX(Settings!$B$11:$B$15,MATCH(5,Settings!$A$11:$A$15,0))-1 | H16: =$A16^5*INDEX(Settings!$C$11:$C$15,MATCH(5,Settings!$A$11:$A$15,0))+5*$A16^4*(1-$A16)*INDEX(Settings!$D$11:$D$15,MATCH(5,Settings!$A$11:$A$15,0))+10*$A16^3*(1-$A16)^2*INDEX(Settings!$E$11:$E$15,MATCH(5,Settings!$A$11:$A$15,0))-1 | I16: =$A16^6*INDEX(Settings!$B$11:$B$15,MATCH(6,Settings!$A$11:$A$15,0))-1 | J16: =$A16^6*INDEX(Settings!$C$11:$C$15,MATCH(6,Settings!$A$11:$A$15,0))+6*$A16^5*(1-$A16)*INDEX(Settings!$D$11:$D$15,MATCH(6,Settings!$A$11:$A$15,0))+15*$A16^4*(1-$A16)^2*INDEX(Settings!$E$11:$E$15,MATCH(6,Settings!$A$11:$A$15,0))-1
A17: 0.54 | B17: =$A17^2*INDEX(Settings!$B$11:$B$15,MATCH(2,Settings!$A$11:$A$15,0))-1 | C17: =$A17^3*INDEX(Settings!$B$11:$B$15,MATCH(3,Settings!$A$11:$A$15,0))-1 | D17: =$A17^3*INDEX(Settings!$C$11:$C$15,MATCH(3,Settings!$A$11:$A$15,0))+3*$A17^2*(1-$A17)*INDEX(Settings!$D$11:$D$15,MATCH(3,Settings!$A$11:$A$15,0))+3*$A17^1*(1-$A17)^2*INDEX(Settings!$E$11:$E$15,MATCH(3,Settings!$A$11:$A$15,0))-1 | E17: =$A17^4*INDEX(Settings!$B$11:$B$15,MATCH(4,Settings!$A$11:$A$15,0))-1 | F17: =$A17^4*INDEX(Settings!$C$11:$C$15,MATCH(4,Settings!$A$11:$A$15,0))+4*$A17^3*(1-$A17)*INDEX(Settings!$D$11:$D$15,MATCH(4,Settings!$A$11:$A$15,0))+6*$A17^2*(1-$A17)^2*INDEX(Settings!$E$11:$E$15,MATCH(4,Settings!$A$11:$A$15,0))-1 | G17: =$A17^5*INDEX(Settings!$B$11:$B$15,MATCH(5,Settings!$A$11:$A$15,0))-1 | H17: =$A17^5*INDEX(Settings!$C$11:$C$15,MATCH(5,Settings!$A$11:$A$15,0))+5*$A17^4*(1-$A17)*INDEX(Settings!$D$11:$D$15,MATCH(5,Settings!$A$11:$A$15,0))+10*$A17^3*(1-$A17)^2*INDEX(Settings!$E$11:$E$15,MATCH(5,Settings!$A$11:$A$15,0))-1 | I17: =$A17^6*INDEX(Settings!$B$11:$B$15,MATCH(6,Settings!$A$11:$A$15,0))-1 | J17: =$A17^6*INDEX(Settings!$C$11:$C$15,MATCH(6,Settings!$A$11:$A$15,0))+6*$A17^5*(1-$A17)*INDEX(Settings!$D$11:$D$15,MATCH(6,Settings!$A$11:$A$15,0))+15*$A17^4*(1-$A17)^2*INDEX(Settings!$E$11:$E$15,MATCH(6,Settings!$A$11:$A$15,0))-1
A18: 0.55 | B18: =$A18^2*INDEX(Settings!$B$11:$B$15,MATCH(2,Settings!$A$11:$A$15,0))-1 | C18: =$A18^3*INDEX(Settings!$B$11:$B$15,MATCH(3,Settings!$A$11:$A$15,0))-1 | D18: =$A18^3*INDEX(Settings!$C$11:$C$15,MATCH(3,Settings!$A$11:$A$15,0))+3*$A18^2*(1-$A18)*INDEX(Settings!$D$11:$D$15,MATCH(3,Settings!$A$11:$A$15,0))+3*$A18^1*(1-$A18)^2*INDEX(Settings!$E$11:$E$15,MATCH(3,Settings!$A$11:$A$15,0))-1 | E18: =$A18^4*INDEX(Settings!$B$11:$B$15,MATCH(4,Settings!$A$11:$A$15,0))-1 | F18: =$A18^4*INDEX(Settings!$C$11:$C$15,MATCH(4,Settings!$A$11:$A$15,0))+4*$A18^3*(1-$A18)*INDEX(Settings!$D$11:$D$15,MATCH(4,Settings!$A$11:$A$15,0))+6*$A18^2*(1-$A18)^2*INDEX(Settings!$E$11:$E$15,MATCH(4,Settings!$A$11:$A$15,0))-1 | G18: =$A18^5*INDEX(Settings!$B$11:$B$15,MATCH(5,Settings!$A$11:$A$15,0))-1 | H18: =$A18^5*INDEX(Settings!$C$11:$C$15,MATCH(5,Settings!$A$11:$A$15,0))+5*$A18^4*(1-$A18)*INDEX(Settings!$D$11:$D$15,MATCH(5,Settings!$A$11:$A$15,0))+10*$A18^3*(1-$A18)^2*INDEX(Settings!$E$11:$E$15,MATCH(5,Settings!$A$11:$A$15,0))-1 | I18: =$A18^6*INDEX(Settings!$B$11:$B$15,MATCH(6,Settings!$A$11:$A$15,0))-1 | J18: =$A18^6*INDEX(Settings!$C$11:$C$15,MATCH(6,Settings!$A$11:$A$15,0))+6*$A18^5*(1-$A18)*INDEX(Settings!$D$11:$D$15,MATCH(6,Settings!$A$11:$A$15,0))+15*$A18^4*(1-$A18)^2*INDEX(Settings!$E$11:$E$15,MATCH(6,Settings!$A$11:$A$15,0))-1
A19: 0.56 | B19: =$A19^2*INDEX(Settings!$B$11:$B$15,MATCH(2,Settings!$A$11:$A$15,0))-1 | C19: =$A19^3*INDEX(Settings!$B$11:$B$15,MATCH(3,Settings!$A$11:$A$15,0))-1 | D19: =$A19^3*INDEX(Settings!$C$11:$C$15,MATCH(3,Settings!$A$11:$A$15,0))+3*$A19^2*(1-$A19)*INDEX(Settings!$D$11:$D$15,MATCH(3,Settings!$A$11:$A$15,0))+3*$A19^1*(1-$A19)^2*INDEX(Settings!$E$11:$E$15,MATCH(3,Settings!$A$11:$A$15,0))-1 | E19: =$A19^4*INDEX(Settings!$B$11:$B$15,MATCH(4,Settings!$A$11:$A$15,0))-1 | F19: =$A19^4*INDEX(Settings!$C$11:$C$15,MATCH(4,Settings!$A$11:$A$15,0))+4*$A19^3*(1-$A19)*INDEX(Settings!$D$11:$D$15,MATCH(4,Settings!$A$11:$A$15,0))+6*$A19^2*(1-$A19)^2*INDEX(Settings!$E$11:$E$15,MATCH(4,Settings!$A$11:$A$15,0))-1 | G19: =$A19^5*INDEX(Settings!$B$11:$B$15,MATCH(5,Settings!$A$11:$A$15,0))-1 | H19: =$A19^5*INDEX(Settings!$C$11:$C$15,MATCH(5,Settings!$A$11:$A$15,0))+5*$A19^4*(1-$A19)*INDEX(Settings!$D$11:$D$15,MATCH(5,Settings!$A$11:$A$15,0))+10*$A19^3*(1-$A19)^2*INDEX(Settings!$E$11:$E$15,MATCH(5,Settings!$A$11:$A$15,0))-1 | I19: =$A19^6*INDEX(Settings!$B$11:$B$15,MATCH(6,Settings!$A$11:$A$15,0))-1 | J19: =$A19^6*INDEX(Settings!$C$11:$C$15,MATCH(6,Settings!$A$11:$A$15,0))+6*$A19^5*(1-$A19)*INDEX(Settings!$D$11:$D$15,MATCH(6,Settings!$A$11:$A$15,0))+15*$A19^4*(1-$A19)^2*INDEX(Settings!$E$11:$E$15,MATCH(6,Settings!$A$11:$A$15,0))-1
A20: 0.57 | B20: =$A20^2*INDEX(Settings!$B$11:$B$15,MATCH(2,Settings!$A$11:$A$15,0))-1 | C20: =$A20^3*INDEX(Settings!$B$11:$B$15,MATCH(3,Settings!$A$11:$A$15,0))-1 | D20: =$A20^3*INDEX(Settings!$C$11:$C$15,MATCH(3,Settings!$A$11:$A$15,0))+3*$A20^2*(1-$A20)*INDEX(Settings!$D$11:$D$15,MATCH(3,Settings!$A$11:$A$15,0))+3*$A20^1*(1-$A20)^2*INDEX(Settings!$E$11:$E$15,MATCH(3,Settings!$A$11:$A$15,0))-1 | E20: =$A20^4*INDEX(Settings!$B$11:$B$15,MATCH(4,Settings!$A$11:$A$15,0))-1 | F20: =$A20^4*INDEX(Settings!$C$11:$C$15,MATCH(4,Settings!$A$11:$A$15,0))+4*$A20^3*(1-$A20)*INDEX(Settings!$D$11:$D$15,MATCH(4,Settings!$A$11:$A$15,0))+6*$A20^2*(1-$A20)^2*INDEX(Settings!$E$11:$E$15,MATCH(4,Settings!$A$11:$A$15,0))-1 | G20: =$A20^5*INDEX(Settings!$B$11:$B$15,MATCH(5,Settings!$A$11:$A$15,0))-1 | H20: =$A20^5*INDEX(Settings!$C$11:$C$15,MATCH(5,Settings!$A$11:$A$15,0))+5*$A20^4*(1-$A20)*INDEX(Settings!$D$11:$D$15,MATCH(5,Settings!$A$11:$A$15,0))+10*$A20^3*(1-$A20)^2*INDEX(Settings!$E$11:$E$15,MATCH(5,Settings!$A$11:$A$15,0))-1 | I20: =$A20^6*INDEX(Settings!$B$11:$B$15,MATCH(6,Settings!$A$11:$A$15,0))-1 | J20: =$A20^6*INDEX(Settings!$C$11:$C$15,MATCH(6,Settings!$A$11:$A$15,0))+6*$A20^5*(1-$A20)*INDEX(Settings!$D$11:$D$15,MATCH(6,Settings!$A$11:$A$15,0))+15*$A20^4*(1-$A20)^2*INDEX(Settings!$E$11:$E$15,MATCH(6,Settings!$A$11:$A$15,0))-1
A21: 0.58 | B21: =$A21^2*INDEX(Settings!$B$11:$B$15,MATCH(2,Settings!$A$11:$A$15,0))-1 | C21: =$A21^3*INDEX(Settings!$B$11:$B$15,MATCH(3,Settings!$A$11:$A$15,0))-1 | D21: =$A21^3*INDEX(Settings!$C$11:$C$15,MATCH(3,Settings!$A$11:$A$15,0))+3*$A21^2*(1-$A21)*INDEX(Settings!$D$11:$D$15,MATCH(3,Settings!$A$11:$A$15,0))+3*$A21^1*(1-$A21)^2*INDEX(Settings!$E$11:$E$15,MATCH(3,Settings!$A$11:$A$15,0))-1 | E21: =$A21^4*INDEX(Settings!$B$11:$B$15,MATCH(4,Settings!$A$11:$A$15,0))-1 | F21: =$A21^4*INDEX(Settings!$C$11:$C$15,MATCH(4,Settings!$A$11:$A$15,0))+4*$A21^3*(1-$A21)*INDEX(Settings!$D$11:$D$15,MATCH(4,Settings!$A$11:$A$15,0))+6*$A21^2*(1-$A21)^2*INDEX(Settings!$E$11:$E$15,MATCH(4,Settings!$A$11:$A$15,0))-1 | G21: =$A21^5*INDEX(Settings!$B$11:$B$15,MATCH(5,Settings!$A$11:$A$15,0))-1 | H21: =$A21^5*INDEX(Settings!$C$11:$C$15,MATCH(5,Settings!$A$11:$A$15,0))+5*$A21^4*(1-$A21)*INDEX(Settings!$D$11:$D$15,MATCH(5,Settings!$A$11:$A$15,0))+10*$A21^3*(1-$A21)^2*INDEX(Settings!$E$11:$E$15,MATCH(5,Settings!$A$11:$A$15,0))-1 | I21: =$A21^6*INDEX(Settings!$B$11:$B$15,MATCH(6,Settings!$A$11:$A$15,0))-1 | J21: =$A21^6*INDEX(Settings!$C$11:$C$15,MATCH(6,Settings!$A$11:$A$15,0))+6*$A21^5*(1-$A21)*INDEX(Settings!$D$11:$D$15,MATCH(6,Settings!$A$11:$A$15,0))+15*$A21^4*(1-$A21)^2*INDEX(Settings!$E$11:$E$15,MATCH(6,Settings!$A$11:$A$15,0))-1
A22: 0.59 | B22: =$A22^2*INDEX(Settings!$B$11:$B$15,MATCH(2,Settings!$A$11:$A$15,0))-1 | C22: =$A22^3*INDEX(Settings!$B$11:$B$15,MATCH(3,Settings!$A$11:$A$15,0))-1 | D22: =$A22^3*INDEX(Settings!$C$11:$C$15,MATCH(3,Settings!$A$11:$A$15,0))+3*$A22^2*(1-$A22)*INDEX(Settings!$D$11:$D$15,MATCH(3,Settings!$A$11:$A$15,0))+3*$A22^1*(1-$A22)^2*INDEX(Settings!$E$11:$E$15,MATCH(3,Settings!$A$11:$A$15,0))-1 | E22: =$A22^4*INDEX(Settings!$B$11:$B$15,MATCH(4,Settings!$A$11:$A$15,0))-1 | F22: =$A22^4*INDEX(Settings!$C$11:$C$15,MATCH(4,Settings!$A$11:$A$15,0))+4*$A22^3*(1-$A22)*INDEX(Settings!$D$11:$D$15,MATCH(4,Settings!$A$11:$A$15,0))+6*$A22^2*(1-$A22)^2*INDEX(Settings!$E$11:$E$15,MATCH(4,Settings!$A$11:$A$15,0))-1 | G22: =$A22^5*INDEX(Settings!$B$11:$B$15,MATCH(5,Settings!$A$11:$A$15,0))-1 | H22: =$A22^5*INDEX(Settings!$C$11:$C$15,MATCH(5,Settings!$A$11:$A$15,0))+5*$A22^4*(1-$A22)*INDEX(Settings!$D$11:$D$15,MATCH(5,Settings!$A$11:$A$15,0))+10*$A22^3*(1-$A22)^2*INDEX(Settings!$E$11:$E$15,MATCH(5,Settings!$A$11:$A$15,0))-1 | I22: =$A22^6*INDEX(Settings!$B$11:$B$15,MATCH(6,Settings!$A$11:$A$15,0))-1 | J22: =$A22^6*INDEX(Settings!$C$11:$C$15,MATCH(6,Settings!$A$11:$A$15,0))+6*$A22^5*(1-$A22)*INDEX(Settings!$D$11:$D$15,MATCH(6,Settings!$A$11:$A$15,0))+15*$A22^4*(1-$A22)^2*INDEX(Settings!$E$11:$E$15,MATCH(6,Settings!$A$11:$A$15,0))-1
